Workbook
Name Slicer_Cleaned_Region: #N/A
Name Slicer_Month: #N/A

Sheet Raw Sales Data
A1: Order ID | B1: Order Date | C1: Region | D1: Sales Rep | E1: Product ID | F1: Product Name | G1: Quantity | H1: Unit Price (KES)
A2: 10008 | B2: 45306 | C2: mombasa | D2: Peter Otieno | E2: P013 | F2: Kitchen Knife Set | G2: 20 | H2: 1350
A3: 10300 | B3: 2024.03.13 | C3: nakuru | D3: Faith Wanjiru | E3: P013 | F3: Kitchen Knife Set | G3: 6 | H3: 1350
A4: 10328 | B4: 45338 | C4: Mombasa | D4: Grace Achieng | E4: P001 | F4: 20L Jerrycan - Blue | G4: 4 | H4: 600
A5: 10216 | B5: 45373 | C5: Eldoret | D5: grace achieng | E5: P015 | F5: Water Dispenser Stand | G5: 10 | H5: 2300
A6: 10065 | B6: 45505 | C6: KISUMU | D6: Mercy Njeri | E6: P006 | F6: Plastic Storage Basket L | G6: 8 | H6: 420
A7: 10222 | B7: 45339 | C7: Mombasa | D7: aisha hassan | E7: P001 | F7: 20L Jerrycan - Blue | G7: 5 | H7: 600
A8: 10140 | B8: 15/01/2024 | C8: Thika | D8: Faith Wanjiru | E8: P012 | F8: Garden Hose 20m | G8: 15 | H8: 1750
A9: 10268 | B9: 2024.02.14 | C9: Mombasa | D9: Faith Wanjiru | E9: P011 | F9: PADLOCK SET (3PC) | G9: 6 | H9: 700
A10: 10025 | B10: 45323 | C10: Kisumu | D10: PETER OTIENO | E10: P013 | F10: Kitchen Knife Set | G10: 2 | H10: 1350
A11: 10205 | B11: 45599 | C11: MOMBASA | D11: Grace Achieng | E11: P008 | F11: USB Wall Charger UC-5 | G11: 2 | H11: 500
A12: 10188 | B12: 45370 | C12: Thika | D12: Peter Otieno | E12: P008 | F12: USB Wall Charger UC-5 | G12: 6 | H12: 500
A13: 10152 | B13: 45321 | C13: Nakuru | D13: faith wanjiru | E13: P008 | F13: USB Wall Charger UC-5 | G13: 12 | H13: 500
A14: 10137 | B14: 45325 | C14: Nakuru | D14: Faith Wanjiru | E14: P008 | F14: USB Wall Charger UC-5 | G14: -5 | H14: 500
A15: 10107 | B15: 45296 | C15: Kisumu | D15: FAITH WANJIRU | E15: P001 | F15: 20L Jerrycan - Blue | G15: 4 | H15: 500
A16: 10067 | B16: 45346 | C16: thika | D16: Samuel Kiptoo | E16: P008 | F16: USB Wall Charger UC-5 | G16: 5 | H16: 500
A17: 10030 | B17: 45445 | C17: Mombasa | D17: Brian Mutua | E17: P013 | F17: Kitchen Knife Set | G17: 15 | H17: 1400
A18: 10109 | B18: 45597 | C18: thika | D18: Brian Mutua | E18: P002 | F18: Solar Lantern SL200 | G18: 8 | H18: 1550
A19: 10218 | B19: 45365 | C19: Thika | D19: Faith Wanjiru | E19: P003 | F19: RECHARGEABLE TORCH RT-10 | G19: 10 | H19: 900
A20: 10228 | B20: 45381 | C20: Thika | D20: Grace Achieng | E20: P014 | F20: LED Bulb 9W (Pack of 4) | G20: 4 | H20: 780
A21: 10111 | B21: 21/01/2024 | C21: Nairobi | D21: PETER OTIENO | E21: P014 | F21: LED Bulb 9W (Pack of 4) | G21: 15 | H21: 830
A22: 10255 | B22: 45446 | C22: Eldoret | D22: Faith Wanjiru | E22: P011 | F22: Padlock Set (3pc) | G22: 20 | H22: 750
A23: 10236 | B23: 45335 | C23: Thika | D23: Faith Wanjiru | E23: P011 | F23: PADLOCK SET (3PC) | G23: 12 | H23: 750
A24: 10055 | B24: 2024.03.27 | C24: Kisumu | D24: John Mwangi | E24: P013 | F24: Kitchen Knife Set | G24: 3 | H24: 1350
A25: 10090 | B25: 45335 | C25: Mombasa | D25: Mercy Njeri | E25: P013 | F25: Kitchen Knife Set | G25: 3 | H25: 1250
A26: 10197 | B26: 45338 | C26: NAKURU | D26: Peter Otieno | E26: P003 | F26: RECHARGEABLE TORCH RT-10 | G26: 1 | H26: 1050
A27: 10242 | B27: 45368 | D27: MERCY NJERI | E27: P007 | F27: MOSQUITO NET - FAMILY SIZE | G27: 20 | H27: 650
A28: 10289 | B28: 18/02/2024 | C28: Nakuru | D28: Peter Otieno | E28: P002 | F28: Solar Lantern SL-200 | G28: 1 | H28: 1450
A29: 10108 | B29: 2024.03.24 | C29: KISUMU | D29: Samuel Kiptoo | E29: P002 | F29: solar lantern sl-200 | G29: 6 | H29: 1500
A30: 10087 | B30: 45342 | D30: John Mwangi | E30: P001 | F30: 20L Jerrycan - Blue | G30: 4 | H30: 550
A31: 10263 | B31: 45328 | C31: Thika | D31: Samuel Kiptoo | E31: P003 | F31: Rechargeable Torch RT-10 | G31: 1 | H31: 950
A32: 10038 | B32: 45376 | C32: Nairobi | D32: Grace Achieng | E32: P011 | F32: Padlock Set (3pc) | G32: 8 | H32: 700
A33: 10148 | B33: 45299 | C33: Eldoret | D33: Brian Mutua | E33: P007 | F33: Mosquito Net - Family Size | G33: 12 | H33: 750
A34: 10180 | B34: 45382 | C34: Eldoret | D34: Brian Mutua | E34: P003 | F34: Rechargeable Torch RT-10 | G34: 15 | H34: 950
A35: 10027 | B35: 45296 | C35: Nairobi | D35: Brian Mutua | E35: P006 | F35: plastic storage basket l | G35: 6 | H35: 470
A36: 10276 | B36: 2024.01.19 | C36: Mombasa | D36: Peter Otieno | E36: P004 | F36: Cooking Gas Burner CB-2 | G36: 15 | H36: 1850
A37: 10184 | B37: 45308 | C37: ELDORET | D37: Aisha Hassan | E37: P013 | F37: Kitchen Knife Set | G37: 6 | H37: 1250
A38: 10062 | B38: 45375 | C38: Mombasa | D38: Aisha Hassan | E38: P001 | F38: 20L Jerrycan - Blue | G38: 3 | H38: 650
A39: 10296 | B39: 45375 | C39: ELDORET | D39: Samuel Kiptoo | E39: P012 | F39: Garden Hose 20m | G39: 15 | H39: 1650
A40: 10186 | B40: 2024.01.12 | C40: Thika | D40: Grace Achieng | E40: P001 | F40: 20L Jerrycan - Blue | G40: 4 | H40: 600
...

Sheet Cleaned Sales Data
A1: Order ID | B1: Order Date | C1: Cleaned Order Date | D1: Region | E1: Cleaned Region | F1: Sales Rep | G1: Cleaned Sales Rep | H1: Product ID | I1: Product Name | J1: Cleaned Product Name | K1: Quantity | L1: New Quantity | M1: Unit Price (KES) | N1: Cleaned Unit Price (KES) | O1: Flags | P1: Cleaned Quantity | Q1: Unit Cost | R1: Category | S1: Revenue | T1: Cost | U1: Profit | V1: Margin % | W1: Month
A2: 10008 | B2: 45306 | C2: 45306 | D2: mombasa | E2: =PROPER(TRIM(D2)) -> Mombasa | F2: Peter Otieno | G2: =PROPER(TRIM(F2)) -> Peter Otieno | H2: P013 | I2: Kitchen Knife Set | J2: =PROPER(TRIM(I2)) -> Kitchen Knife Set | K2: 20 | L2: =IF(K2="",0,K2) -> 20 | M2: 1350 | N2: =IF(M2="",0,M2) -> 1350 | O2: =IF(L2<0,"NEGATIVE QUANTITY","") | P2: =ABS(L2) -> 20 | Q2: =VLOOKUP(H2,'Product Cost Lookup'!A:D,4,FALSE) -> 800 | R2: =VLOOKUP(H2,'Product Cost Lookup'!A:D,3,FALSE) -> Kitchenware | S2: =P2*N2 -> 27000 | T2: =P2*Q2 -> 16000 | U2: =S2-T2 -> 11000 | V2: =IF(S2=0,0,U2/S2) -> 0.40740741 | W2: =TEXT(C2,"mmm") -> Jan
A3: 10300 | B3: 45364 | C3: 45364 | D3: nakuru | E3: =PROPER(TRIM(D3)) -> Nakuru | F3: Faith Wanjiru | G3: =PROPER(TRIM(F3)) -> Faith Wanjiru | H3: P013 | I3: Kitchen Knife Set | J3: =PROPER(TRIM(I3)) -> Kitchen Knife Set | K3: 6 | L3: =IF(K3="",0,K3) -> 6 | M3: 1350 | N3: =IF(M3="",0,M3) -> 1350 | O3: =IF(L3<0,"NEGATIVE QUANTITY","") | P3: =ABS(L3) -> 6 | Q3: =VLOOKUP(H3,'Product Cost Lookup'!A:D,4,FALSE) -> 800 | R3: =VLOOKUP(H3,'Product Cost Lookup'!A:D,3,FALSE) -> Kitchenware | S3: =P3*N3 -> 8100 | T3: =P3*Q3 -> 4800 | U3: =S3-T3 -> 3300 | V3: =IF(S3=0,0,U3/S3) -> 0.40740741 | W3: =TEXT(C3,"mmm") -> Mar
A4: 10328 | B4: 45338 | C4: 45338 | D4: Mombasa | E4: =PROPER(TRIM(D4)) -> Mombasa | F4: Grace Achieng | G4: =PROPER(TRIM(F4)) -> Grace Achieng | H4: P001 | I4: 20L Jerrycan - Blue | J4: =PROPER(TRIM(I4)) -> 20L Jerrycan - Blue | K4: 4 | L4: =IF(K4="",0,K4) -> 4 | M4: 600 | N4: =IF(M4="",0,M4) -> 600 | O4: =IF(L4<0,"NEGATIVE QUANTITY","") | P4: =ABS(L4) -> 4 | Q4: =VLOOKUP(H4,'Product Cost Lookup'!A:D,4,FALSE) -> 350 | R4: =VLOOKUP(H4,'Product Cost Lookup'!A:D,3,FALSE) -> Household | S4: =P4*N4 -> 2400 | T4: =P4*Q4 -> 1400 | U4: =S4-T4 -> 1000 | V4: =IF(S4=0,0,U4/S4) -> 0.41666667 | W4: =TEXT(C4,"mmm") -> Feb
A5: 10216 | B5: 45373 | C5: 45373 | D5: Eldoret | E5: =PROPER(TRIM(D5)) -> Eldoret | F5: grace achieng | G5: =PROPER(TRIM(F5)) -> Grace Achieng | H5: P015 | I5: Water Dispenser Stand | J5: =PROPER(TRIM(I5)) -> Water Dispenser Stand | K5: 10 | L5: =IF(K5="",0,K5) -> 10 | M5: 2300 | N5: =IF(M5="",0,M5) -> 2300 | O5: =IF(L5<0,"NEGATIVE QUANTITY","") | P5: =ABS(L5) -> 10 | Q5: =VLOOKUP(H5,'Product Cost Lookup'!A:D,4,FALSE) -> 1500 | R5: =VLOOKUP(H5,'Product Cost Lookup'!A:D,3,FALSE) -> Household | S5: =P5*N5 -> 23000 | T5: =P5*Q5 -> 15000 | U5: =S5-T5 -> 8000 | V5: =IF(S5=0,0,U5/S5) -> 0.34782609 | W5: =TEXT(C5,"mmm") -> Mar
A6: 10065 | B6: 45505 | C6: 45505 | D6: KISUMU | E6: =PROPER(TRIM(D6)) -> Kisumu | F6: Mercy Njeri | G6: =PROPER(TRIM(F6)) -> Mercy Njeri | H6: P006 | I6: Plastic Storage Basket L | J6: =PROPER(TRIM(I6)) -> Plastic Storage Basket L | K6: 8 | L6: =IF(K6="",0,K6) -> 8 | M6: 420 | N6: =IF(M6="",0,M6) -> 420 | O6: =IF(L6<0,"NEGATIVE QUANTITY","") | P6: =ABS(L6) -> 8 | Q6: =VLOOKUP(H6,'Product Cost Lookup'!A:D,4,FALSE) -> 250 | R6: =VLOOKUP(H6,'Product Cost Lookup'!A:D,3,FALSE) -> Household | S6: =P6*N6 -> 3360 | T6: =P6*Q6 -> 2000 | U6: =S6-T6 -> 1360 | V6: =IF(S6=0,0,U6/S6) -> 0.4047619 | W6: =TEXT(C6,"mmm") -> Aug
A7: 10222 | B7: 45339 | C7: 45339 | D7: Mombasa | E7: =PROPER(TRIM(D7)) -> Mombasa | F7: aisha hassan | G7: =PROPER(TRIM(F7)) -> Aisha Hassan | H7: P001 | I7: 20L Jerrycan - Blue | J7: =PROPER(TRIM(I7)) -> 20L Jerrycan - Blue | K7: 5 | L7: =IF(K7="",0,K7) -> 5 | M7: 600 | N7: =IF(M7="",0,M7) -> 600 | O7: =IF(L7<0,"NEGATIVE QUANTITY","") | P7: =ABS(L7) -> 5 | Q7: =VLOOKUP(H7,'Product Cost Lookup'!A:D,4,FALSE) -> 350 | R7: =VLOOKUP(H7,'Product Cost Lookup'!A:D,3,FALSE) -> Household | S7: =P7*N7 -> 3000 | T7: =P7*Q7 -> 1750 | U7: =S7-T7 -> 1250 | V7: =IF(S7=0,0,U7/S7) -> 0.41666667 | W7: =TEXT(C7,"mmm") -> Feb
A8: 10140 | B8: 45306 | C8: 45306 | D8: Thika | E8: =PROPER(TRIM(D8)) -> Thika | F8: Faith Wanjiru | G8: =PROPER(TRIM(F8)) -> Faith Wanjiru | H8: P012 | I8: Garden Hose 20m | J8: =PROPER(TRIM(I8)) -> Garden Hose 20M | K8: 15 | L8: =IF(K8="",0,K8) -> 15 | M8: 1750 | N8: =IF(M8="",0,M8) -> 1750 | O8: =IF(L8<0,"NEGATIVE QUANTITY","") | P8: =ABS(L8) -> 15 | Q8: =VLOOKUP(H8,'Product Cost Lookup'!A:D,4,FALSE) -> 1100 | R8: =VLOOKUP(H8,'Product Cost Lookup'!A:D,3,FALSE) -> Hardware | S8: =P8*N8 -> 26250 | T8: =P8*Q8 -> 16500 | U8: =S8-T8 -> 9750 | V8: =IF(S8=0,0,U8/S8) -> 0.37142857 | W8: =TEXT(C8,"mmm") -> Jan
A9: 10268 | B9: 45336 | C9: 45336 | D9: Mombasa | E9: =PROPER(TRIM(D9)) -> Mombasa | F9: Faith Wanjiru | G9: =PROPER(TRIM(F9)) -> Faith Wanjiru | H9: P011 | I9: PADLOCK SET (3PC) | J9: =PROPER(TRIM(I9)) -> Padlock Set (3Pc) | K9: 6 | L9: =IF(K9="",0,K9) -> 6 | M9: 700 | N9: =IF(M9="",0,M9) -> 700 | O9: =IF(L9<0,"NEGATIVE QUANTITY","") | P9: =ABS(L9) -> 6 | Q9: =VLOOKUP(H9,'Product Cost Lookup'!A:D,4,FALSE) -> 450 | R9: =VLOOKUP(H9,'Product Cost Lookup'!A:D,3,FALSE) -> Hardware | S9: =P9*N9 -> 4200 | T9: =P9*Q9 -> 2700 | U9: =S9-T9 -> 1500 | V9: =IF(S9=0,0,U9/S9) -> 0.35714286 | W9: =TEXT(C9,"mmm") -> Feb
A10: 10025 | B10: 45323 | C10: 45323 | D10: Kisumu | E10: =PROPER(TRIM(D10)) -> Kisumu | F10: PETER OTIENO | G10: =PROPER(TRIM(F10)) -> Peter Otieno | H10: P013 | I10: Kitchen Knife Set | J10: =PROPER(TRIM(I10)) -> Kitchen Knife Set | K10: 2 | L10: =IF(K10="",0,K10) -> 2 | M10: 1350 | N10: =IF(M10="",0,M10) -> 1350 | O10: =IF(L10<0,"NEGATIVE QUANTITY","") | P10: =ABS(L10) -> 2 | Q10: =VLOOKUP(H10,'Product Cost Lookup'!A:D,4,FALSE) -> 800 | R10: =VLOOKUP(H10,'Product Cost Lookup'!A:D,3,FALSE) -> Kitchenware | S10: =P10*N10 -> 2700 | T10: =P10*Q10 -> 1600 | U10: =S10-T10 -> 1100 | V10: =IF(S10=0,0,U10/S10) -> 0.40740741 | W10: =TEXT(C10,"mmm") -> Feb
A11: 10205 | B11: 45599 | C11: 45599 | D11: MOMBASA | E11: =PROPER(TRIM(D11)) -> Mombasa | F11: Grace Achieng | G11: =PROPER(TRIM(F11)) -> Grace Achieng | H11: P008 | I11: USB Wall Charger UC-5 | J11: =PROPER(TRIM(I11)) -> Usb Wall Charger Uc-5 | K11: 2 | L11: =IF(K11="",0,K11) -> 2 | M11: 500 | N11: =IF(M11="",0,M11) -> 500 | O11: =IF(L11<0,"NEGATIVE QUANTITY","") | P11: =ABS(L11) -> 2 | Q11: =VLOOKUP(H11,'Product Cost Lookup'!A:D,4,FALSE) -> 300 | R11: =VLOOKUP(H11,'Product Cost Lookup'!A:D,3,FALSE) -> Electronics | S11: =P11*N11 -> 1000 | T11: =P11*Q11 -> 600 | U11: =S11-T11 -> 400 | V11: =IF(S11=0,0,U11/S11) -> 0.4 | W11: =TEXT(C11,"mmm") -> Nov
A12: 10188 | B12: 45370 | C12: 45370 | D12: Thika | E12: =PROPER(TRIM(D12)) -> Thika | F12: Peter Otieno | G12: =PROPER(TRIM(F12)) -> Peter Otieno | H12: P008 | I12: USB Wall Charger UC-5 | J12: =PROPER(TRIM(I12)) -> Usb Wall Charger Uc-5 | K12: 6 | L12: =IF(K12="",0,K12) -> 6 | M12: 500 | N12: =IF(M12="",0,M12) -> 500 | O12: =IF(L12<0,"NEGATIVE QUANTITY","") | P12: =ABS(L12) -> 6 | Q12: =VLOOKUP(H12,'Product Cost Lookup'!A:D,4,FALSE) -> 300 | R12: =VLOOKUP(H12,'Product Cost Lookup'!A:D,3,FALSE) -> Electronics | S12: =P12*N12 -> 3000 | T12: =P12*Q12 -> 1800 | U12: =S12-T12 -> 1200 | V12: =IF(S12=0,0,U12/S12) -> 0.4 | W12: =TEXT(C12,"mmm") -> Mar
A13: 10152 | B13: 45321 | C13: 45321 | D13: Nakuru | E13: =PROPER(TRIM(D13)) -> Nakuru | F13: faith wanjiru | G13: =PROPER(TRIM(F13)) -> Faith Wanjiru | H13: P008 | I13: USB Wall Charger UC-5 | J13: =PROPER(TRIM(I13)) -> Usb Wall Charger Uc-5 | K13: 12 | L13: =IF(K13="",0,K13) -> 12 | M13: 500 | N13: =IF(M13="",0,M13) -> 500 | O13: =IF(L13<0,"NEGATIVE QUANTITY","") | P13: =ABS(L13) -> 12 | Q13: =VLOOKUP(H13,'Product Cost Lookup'!A:D,4,FALSE) -> 300 | R13: =VLOOKUP(H13,'Product Cost Lookup'!A:D,3,FALSE) -> Electronics | S13: =P13*N13 -> 6000 | T13: =P13*Q13 -> 3600 | U13: =S13-T13 -> 2400 | V13: =IF(S13=0,0,U13/S13) -> 0.4 | W13: =TEXT(C13,"mmm") -> Jan
... A20: 10228 | B20: 45381 | C20: 45381 | D20: Thika | E20: =PROPER(TRIM(D20)) -> Thika | F20: Grace Achieng | G20: =PROPER(TRIM(F20)) -> Grace Achieng | H20: P014 | I20: LED Bulb 9W (Pack of 4) | J20: =PROPER(TRIM(I20)) -> Led Bulb 9W (Pack Of 4) | K20: 4 | L20: =IF(K20="",0,K20) -> 4 | M20: 780 | N20: =IF(M20="",0,M20) -> 780 | O20: =IF(L20<0,"NEGATIVE QUANTITY","") | P20: =ABS(L20) -> 4 | Q20: =VLOOKUP(H20,'Product Cost Lookup'!A:D,4,FALSE) -> 480 | R20: =VLOOKUP(H20,'Product Cost Lookup'!A:D,3,FALSE) -> Electronics | S20: =P20*N20 -> 3120 | T20: =P20*Q20 -> 1920 | U20: =S20-T20 -> 1200 | V20: =IF(S20=0,0,U20/S20) -> 0.38461538 | W20: =TEXT(C20,"mmm") -> Mar
A21: 10111 | B21: 21/01/2024 | C21: 45312 | D21: Nairobi | E21: =PROPER(TRIM(D21)) -> Nairobi | F21: PETER OTIENO | G21: =PROPER(TRIM(F21)) -> Peter Otieno | H21: P014 | I21: LED Bulb 9W (Pack of 4) | J21: =PROPER(TRIM(I21)) -> Led Bulb 9W (Pack Of 4) | K21: 15 | L21: =IF(K21="",0,K21) -> 15 | M21: 830 | N21: =IF(M21="",0,M21) -> 830 | O21: =IF(L21<0,"NEGATIVE QUANTITY","") | P21: =ABS(L21) -> 15 | Q21: =VLOOKUP(H21,'Product Cost Lookup'!A:D,4,FALSE) -> 480 | R21: =VLOOKUP(H21,'Product Cost Lookup'!A:D,3,FALSE) -> Electronics | S21: =P21*N21 -> 12450 | T21: =P21*Q21 -> 7200 | U21: =S21-T21 -> 5250 | V21: =IF(S21=0,0,U21/S21) -> 0.42168675 | W21: =TEXT(C21,"mmm") -> Jan
A22: 10255 | B22: 45446 | C22: 45446 | D22: Eldoret | E22: =PROPER(TRIM(D22)) -> Eldoret | F22: Faith Wanjiru | G22: =PROPER(TRIM(F22)) -> Faith Wanjiru | H22: P011 | I22: Padlock Set (3pc) | J22: =PROPER(TRIM(I22)) -> Padlock Set (3Pc) | K22: 20 | L22: =IF(K22="",0,K22) -> 20 | M22: 750 | N22: =IF(M22="",0,M22) -> 750 | O22: =IF(L22<0,"NEGATIVE QUANTITY","") | P22: =ABS(L22) -> 20 | Q22: =VLOOKUP(H22,'Product Cost Lookup'!A:D,4,FALSE) -> 450 | R22: =VLOOKUP(H22,'Product Cost Lookup'!A:D,3,FALSE) -> Hardware | S22: =P22*N22 -> 15000 | T22: =P22*Q22 -> 9000 | U22: =S22-T22 -> 6000 | V22: =IF(S22=0,0,U22/S22) -> 0.4 | W22: =TEXT(C22,"mmm") -> Jun
A23: 10236 | B23: 45335 | C23: 45335 | D23: Thika | E23: =PROPER(TRIM(D23)) -> Thika | F23: Faith Wanjiru | G23: =PROPER(TRIM(F23)) -> Faith Wanjiru | H23: P011 | I23: PADLOCK SET (3PC) | J23: =PROPER(TRIM(I23)) -> Padlock Set (3Pc) | K23: 12 | L23: =IF(K23="",0,K23) -> 12 | M23: 750 | N23: =IF(M23="",0,M23) -> 750 | O23: =IF(L23<0,"NEGATIVE QUANTITY","") | P23: =ABS(L23) -> 12 | Q23: =VLOOKUP(H23,'Product Cost Lookup'!A:D,4,FALSE) -> 450 | R23: =VLOOKUP(H23,'Product Cost Lookup'!A:D,3,FALSE) -> Hardware | S23: =P23*N23 -> 9000 | T23: =P23*Q23 -> 5400 | U23: =S23-T23 -> 3600 | V23: =IF(S23=0,0,U23/S23) -> 0.4 | W23: =TEXT(C23,"mmm") -> Feb
A24: 10055 | B24: 45378 | C24: 45378 | D24: Kisumu | E24: =PROPER(TRIM(D24)) -> Kisumu | F24: John Mwangi | G24: =PROPER(TRIM(F24)) -> John Mwangi | H24: P013 | I24: Kitchen Knife Set | J24: =PROPER(TRIM(I24)) -> Kitchen Knife Set | K24: 3 | L24: =IF(K24="",0,K24) -> 3 | M24: 1350 | N24: =IF(M24="",0,M24) -> 1350 | O24: =IF(L24<0,"NEGATIVE QUANTITY","") | P24: =ABS(L24) -> 3 | Q24: =VLOOKUP(H24,'Product Cost Lookup'!A:D,4,FALSE) -> 800 | R24: =VLOOKUP(H24,'Product Cost Lookup'!A:D,3,FALSE) -> Kitchenware | S24: =P24*N24 -> 4050 | T24: =P24*Q24 -> 2400 | U24: =S24-T24 -> 1650 | V24: =IF(S24=0,0,U24/S24) -> 0.40740741 | W24: =TEXT(C24,"mmm") -> Mar
A25: 10090 | B25: 45335 | C25: 45335 | D25: Mombasa | E25: =PROPER(TRIM(D25)) -> Mombasa | F25: Mercy Njeri | G25: =PROPER(TRIM(F25)) -> Mercy Njeri | H25: P013 | I25: Kitchen Knife Set | J25: =PROPER(TRIM(I25)) -> Kitchen Knife Set | K25: 3 | L25: =IF(K25="",0,K25) -> 3 | M25: 1250 | N25: =IF(M25="",0,M25) -> 1250 | O25: =IF(L25<0,"NEGATIVE QUANTITY","") | P25: =ABS(L25) -> 3 | Q25: =VLOOKUP(H25,'Product Cost Lookup'!A:D,4,FALSE) -> 800 | R25: =VLOOKUP(H25,'Product Cost Lookup'!A:D,3,FALSE) -> Kitchenware | S25: =P25*N25 -> 3750 | T25: =P25*Q25 -> 2400 | U25: =S25-T25 -> 1350 | V25: =IF(S25=0,0,U25/S25) -> 0.36 | W25: =TEXT(C25,"mmm") -> Feb
A26: 10197 | B26: 45338 | C26: 45338 | D26: NAKURU | E26: =PROPER(TRIM(D26)) -> Nakuru | F26: Peter Otieno | G26: =PROPER(TRIM(F26)) -> Peter Otieno | H26: P003 | I26: RECHARGEABLE TORCH RT-10 | J26: =PROPER(TRIM(I26)) -> Rechargeable Torch Rt-10 | K26: 1 | L26: =IF(K26="",0,K26) -> 1 | M26: 1050 | N26: =IF(M26="",0,M26) -> 1050 | O26: =IF(L26<0,"NEGATIVE QUANTITY","") | P26: =ABS(L26) -> 1 | Q26: =VLOOKUP(H26,'Product Cost Lookup'!A:D,4,FALSE) -> 600 | R26: =VLOOKUP(H26,'Product Cost Lookup'!A:D,3,FALSE) -> Electronics | S26: =P26*N26 -> 1050 | T26: =P26*Q26 -> 600 | U26: =S26-T26 -> 450 | V26: =IF(S26=0,0,U26/S26) -> 0.42857143 | W26: =TEXT(C26,"mmm") -> Feb
A27: 10242 | B27: 45368 | C27: 45368 | E27: =IF(TRIM(D27)="","Unknown",PROPER(TRIM(D27))) -> Unknown | F27: MERCY NJERI | G27: =PROPER(TRIM(F27)) -> Mercy Njeri | H27: P007 | I27: MOSQUITO NET - FAMILY SIZE | J27: =PROPER(TRIM(I27)) -> Mosquito Net - Family Size | K27: 20 | L27: =IF(K27="",0,K27) -> 20 | M27: 650 | N27: =IF(M27="",0,M27) -> 650 | O27: =IF(L27<0,"NEGATIVE QUANTITY","") | P27: =ABS(L27) -> 20 | Q27: =VLOOKUP(H27,'Product Cost Lookup'!A:D,4,FALSE) -> 400 | R27: =VLOOKUP(H27,'Product Cost Lookup'!A:D,3,FALSE) -> Household | S27: =P27*N27 -> 13000 | T27: =P27*Q27 -> 8000 | U27: =S27-T27 -> 5000 | V27: =IF(S27=0,0,U27/S27) -> 0.38461538 | W27: =TEXT(C27,"mmm") -> Mar
A28: 10289 | B28: 18/02/2024 | C28: 45340 | D28: Nakuru | E28: =IF(TRIM(D28)="","Unknown",PROPER(TRIM(D28))) -> Nakuru | F28: Peter Otieno | G28: =PROPER(TRIM(F28)) -> Peter Otieno | H28: P002 | I28: Solar Lantern SL-200 | J28: =PROPER(TRIM(I28)) -> Solar Lantern Sl-200 | K28: 1 | L28: =IF(K28="",0,K28) -> 1 | M28: 1450 | N28: =IF(M28="",0,M28) -> 1450 | O28: =IF(L28<0,"NEGATIVE QUANTITY","") | P28: =ABS(L28) -> 1 | Q28: =VLOOKUP(H28,'Product Cost Lookup'!A:D,4,FALSE) -> 900 | R28: =VLOOKUP(H28,'Product Cost Lookup'!A:D,3,FALSE) -> Electronics | S28: =P28*N28 -> 1450 | T28: =P28*Q28 -> 900 | U28: =S28-T28 -> 550 | V28: =IF(S28=0,0,U28/S28) -> 0.37931034 | W28: =TEXT(C28,"mmm") -> Feb
A29: 10108 | B29: 45375 | C29: 45375 | D29: KISUMU | E29: =IF(TRIM(D29)="","Unknown",PROPER(TRIM(D29))) -> Kisumu | F29: Samuel Kiptoo | G29: =PROPER(TRIM(F29)) -> Samuel Kiptoo | H29: P002 | I29: solar lantern sl-200 | J29: =PROPER(TRIM(I29)) -> Solar Lantern Sl-200 | K29: 6 | L29: =IF(K29="",0,K29) -> 6 | M29: 1500 | N29: =IF(M29="",0,M29) -> 1500 | O29: =IF(L29<0,"NEGATIVE QUANTITY","") | P29: =ABS(L29) -> 6 | Q29: =VLOOKUP(H29,'Product Cost Lookup'!A:D,4,FALSE) -> 900 | R29: =VLOOKUP(H29,'Product Cost Lookup'!A:D,3,FALSE) -> Electronics | S29: =P29*N29 -> 9000 | T29: =P29*Q29 -> 5400 | U29: =S29-T29 -> 3600 | V29: =IF(S29=0,0,U29/S29) -> 0.4 | W29: =TEXT(C29,"mmm") -> Mar
A30: 10087 | B30: 45342 | C30: 45342 | E30: =IF(TRIM(D30)="","Unknown",PROPER(TRIM(D30))) -> Unknown | F30: John Mwangi | G30: =PROPER(TRIM(F30)) -> John Mwangi | H30: P001 | I30: 20L Jerrycan - Blue | J30: =PROPER(TRIM(I30)) -> 20L Jerrycan - Blue | K30: 4 | L30: =IF(K30="",0,K30) -> 4 | M30: 550 | N30: =IF(M30="",0,M30) -> 550 | O30: =IF(L30<0,"NEGATIVE QUANTITY","") | P30: =ABS(L30) -> 4 | Q30: =VLOOKUP(H30,'Product Cost Lookup'!A:D,4,FALSE) -> 350 | R30: =VLOOKUP(H30,'Product Cost Lookup'!A:D,3,FALSE) -> Household | S30: =P30*N30 -> 2200 | T30: =P30*Q30 -> 1400 | U30: =S30-T30 -> 800 | V30: =IF(S30=0,0,U30/S30) -> 0.36363636 | W30: =TEXT(C30,"mmm") -> Feb
A31: 10263 | B31: 45328 | C31: 45328 | D31: Thika | E31: =IF(TRIM(D31)="","Unknown",PROPER(TRIM(D31))) -> Thika | F31: Samuel Kiptoo | G31: =PROPER(TRIM(F31)) -> Samuel Kiptoo | H31: P003 | I31: Rechargeable Torch RT-10 | J31: =PROPER(TRIM(I31)) -> Rechargeable Torch Rt-10 | K31: 1 | L31: =IF(K31="",0,K31) -> 1 | M31: 950 | N31: =IF(M31="",0,M31) -> 950 | O31: =IF(L31<0,"NEGATIVE QUANTITY","") | P31: =ABS(L31) -> 1 | Q31: =VLOOKUP(H31,'Product Cost Lookup'!A:D,4,FALSE) -> 600 | R31: =VLOOKUP(H31,'Product Cost Lookup'!A:D,3,FALSE) -> Electronics | S31: =P31*N31 -> 950 | T31: =P31*Q31 -> 600 | U31: =S31-T31 -> 350 | V31: =IF(S31=0,0,U31/S31) -> 0.36842105 | W31: =TEXT(C31,"mmm") -> Feb
A32: 10038 | B32: 45376 | C32: 45376 | D32: Nairobi | E32: =IF(TRIM(D32)="","Unknown",PROPER(TRIM(D32))) -> Nairobi | F32: Grace Achieng | G32: =PROPER(TRIM(F32)) -> Grace Achieng | H32: P011 | I32: Padlock Set (3pc) | J32: =PROPER(TRIM(I32)) -> Padlock Set (3Pc) | K32: 8 | L32: =IF(K32="",0,K32) -> 8 | M32: 700 | N32: =IF(M32="",0,M32) -> 700 | O32: =IF(L32<0,"NEGATIVE QUANTITY","") | P32: =ABS(L32) -> 8 | Q32: =VLOOKUP(H32,'Product Cost Lookup'!A:D,4,FALSE) -> 450 | R32: =VLOOKUP(H32,'Product Cost Lookup'!A:D,3,FALSE) -> Hardware | S32: =P32*N32 -> 5600 | T32: =P32*Q32 -> 3600 | U32: =S32-T32 -> 2000 | V32: =IF(S32=0,0,U32/S32) -> 0.35714286 | W32: =TEXT(C32,"mmm") -> Mar
A33: 10148 | B33: 45299 | C33: 45299 | D33: Eldoret | E33: =IF(TRIM(D33)="","Unknown",PROPER(TRIM(D33))) -> Eldoret | F33: Brian Mutua | G33: =PROPER(TRIM(F33)) -> Brian Mutua | H33: P007 | I33: Mosquito Net - Family Size | J33: =PROPER(TRIM(I33)) -> Mosquito Net - Family Size | K33: 12 | L33: =IF(K33="",0,K33) -> 12 | M33: 750 | N33: =IF(M33="",0,M33) -> 750 | O33: =IF(L33<0,"NEGATIVE QUANTITY","") | P33: =ABS(L33) -> 12 | Q33: =VLOOKUP(H33,'Product Cost Lookup'!A:D,4,FALSE) -> 400 | R33: =VLOOKUP(H33,'Product Cost Lookup'!A:D,3,FALSE) -> Household | S33: =P33*N33 -> 9000 | T33: =P33*Q33 -> 4800 | U33: =S33-T33 -> 4200 | V33: =IF(S33=0,0,U33/S33) -> 0.46666667 | W33: =TEXT(C33,"mmm") -> Jan
A34: 10180 | B34: 45382 | C34: 45382 | D34: Eldoret | E34: =IF(TRIM(D34)="","Unknown",PROPER(TRIM(D34))) -> Eldoret | F34: Brian Mutua | G34: =PROPER(TRIM(F34)) -> Brian Mutua | H34: P003 | I34: Rechargeable Torch RT-10 | J34: =PROPER(TRIM(I34)) -> Rechargeable Torch Rt-10 | K34: 15 | L34: =IF(K34="",0,K34) -> 15 | M34: 950 | N34: =IF(M34="",0,M34) -> 950 | O34: =IF(L34<0,"NEGATIVE QUANTITY","") | P34: =ABS(L34) -> 15 | Q34: =VLOOKUP(H34,'Product Cost Lookup'!A:D,4,FALSE) -> 600 | R34: =VLOOKUP(H34,'Product Cost Lookup'!A:D,3,FALSE) -> Electronics | S34: =P34*N34 -> 14250 | T34: =P34*Q34 -> 9000 | U34: =S34-T34 -> 5250 | V34: =IF(S34=0,0,U34/S34) -> 0.36842105 | W34: =TEXT(C34,"mmm") -> Mar
A35: 10027 | B35: 45296 | C35: 45296 | D35: Nairobi | E35: =IF(TRIM(D35)="","Unknown",PROPER(TRIM(D35))) -> Nairobi | F35: Brian Mutua | G35: =PROPER(TRIM(F35)) -> Brian Mutua | H35: P006 | I35: plastic storage basket l | J35: =PROPER(TRIM(I35)) -> Plastic Storage Basket L | K35: 6 | L35: =IF(K35="",0,K35) -> 6 | M35: 470 | N35: =IF(M35="",0,M35) -> 470 | O35: =IF(L35<0,"NEGATIVE QUANTITY","") | P35: =ABS(L35) -> 6 | Q35: =VLOOKUP(H35,'Product Cost Lookup'!A:D,4,FALSE) -> 250 | R35: =VLOOKUP(H35,'Product Cost Lookup'!A:D,3,FALSE) -> Household | S35: =P35*N35 -> 2820 | T35: =P35*Q35 -> 1500 | U35: =S35-T35 -> 1320 | V35: =IF(S35=0,0,U35/S35) -> 0.46808511 | W35: =TEXT(C35,"mmm") -> Jan
A36: 10276 | B36: 45310 | C36: 45310 | D36: Mombasa | E36: =IF(TRIM(D36)="","Unknown",PROPER(TRIM(D36))) -> Mombasa | F36: Peter Otieno | G36: =PROPER(TRIM(F36)) -> Peter Otieno | H36: P004 | I36: Cooking Gas Burner CB-2 | J36: =PROPER(TRIM(I36)) -> Cooking Gas Burner Cb-2 | K36: 15 | L36: =IF(K36="",0,K36) -> 15 | M36: 1850 | N36: =IF(M36="",0,M36) -> 1850 | O36: =IF(L36<0,"NEGATIVE QUANTITY","") | P36: =ABS(L36) -> 15 | Q36: =VLOOKUP(H36,'Product Cost Lookup'!A:D,4,FALSE) -> 1200 | R36: =VLOOKUP(H36,'Product Cost Lookup'!A:D,3,FALSE) -> Kitchenware | S36: =P36*N36 -> 27750 | T36: =P36*Q36 -> 18000 | U36: =S36-T36 -> 9750 | V36: =IF(S36=0,0,U36/S36) -> 0.35135135 | W36: =TEXT(C36,"mmm") -> Jan
A37: 10184 | B37: 45308 | C37: 45308 | D37: ELDORET | E37: =IF(TRIM(D37)="","Unknown",PROPER(TRIM(D37))) -> Eldoret | F37: Aisha Hassan | G37: =PROPER(TRIM(F37)) -> Aisha Hassan | H37: P013 | I37: Kitchen Knife Set | J37: =PROPER(TRIM(I37)) -> Kitchen Knife Set | K37: 6 | L37: =IF(K37="",0,K37) -> 6 | M37: 1250 | N37: =IF(M37="",0,M37) -> 1250 | O37: =IF(L37<0,"NEGATIVE QUANTITY","") | P37: =ABS(L37) -> 6 | Q37: =VLOOKUP(H37,'Product Cost Lookup'!A:D,4,FALSE) -> 800 | R37: =VLOOKUP(H37,'Product Cost Lookup'!A:D,3,FALSE) -> Kitchenware | S37: =P37*N37 -> 7500 | T37: =P37*Q37 -> 4800 | U37: =S37-T37 -> 2700 | V37: =IF(S37=0,0,U37/S37) -> 0.36 | W37: =TEXT(C37,"mmm") -> Jan
A38: 10062 | B38: 45375 | C38: 45375 | D38: Mombasa | E38: =IF(TRIM(D38)="","Unknown",PROPER(TRIM(D38))) -> Mombasa | F38: Aisha Hassan | G38: =PROPER(TRIM(F38)) -> Aisha Hassan | H38: P001 | I38: 20L Jerrycan - Blue | J38: =PROPER(TRIM(I38)) -> 20L Jerrycan - Blue | K38: 3 | L38: =IF(K38="",0,K38) -> 3 | M38: 650 | N38: =IF(M38="",0,M38) -> 650 | O38: =IF(L38<0,"NEGATIVE QUANTITY","") | P38: =ABS(L38) -> 3 | Q38: =VLOOKUP(H38,'Product Cost Lookup'!A:D,4,FALSE) -> 350 | R38: =VLOOKUP(H38,'Product Cost Lookup'!A:D,3,FALSE) -> Household | S38: =P38*N38 -> 1950 | T38: =P38*Q38 -> 1050 | U38: =S38-T38 -> 900 | V38: =IF(S38=0,0,U38/S38) -> 0.46153846 | W38: =TEXT(C38,"mmm") -> Mar
A39: 10296 | B39: 45375 | C39: 45375 | D39: ELDORET | E39: =IF(TRIM(D39)="","Unknown",PROPER(TRIM(D39))) -> Eldoret | F39: Samuel Kiptoo | G39: =PROPER(TRIM(F39)) -> Samuel Kiptoo | H39: P012 | I39: Garden Hose 20m | J39: =PROPER(TRIM(I39)) -> Garden Hose 20M | K39: 15 | L39: =IF(K39="",0,K39) -> 15 | M39: 1650 | N39: =IF(M39="",0,M39) -> 1650 | O39: =IF(L39<0,"NEGATIVE QUANTITY","") | P39: =ABS(L39) -> 15 | Q39: =VLOOKUP(H39,'Product Cost Lookup'!A:D,4,FALSE) -> 1100 | R39: =VLOOKUP(H39,'Product Cost Lookup'!A:D,3,FALSE) -> Hardware | S39: =P39*N39 -> 24750 | T39: =P39*Q39 -> 16500 | U39: =S39-T39 -> 8250 | V39: =IF(S39=0,0,U39/S39) -> 0.33333333 | W39: =TEXT(C39,"mmm") -> Mar
A40: 10186 | B40: 45303 | C40: 45303 | D40: Thika | E40: =IF(TRIM(D40)="","Unknown",PROPER(TRIM(D40))) -> Thika | F40: Grace Achieng | G40: =PROPER(TRIM(F40)) -> Grace Achieng | H40: P001 | I40: 20L Jerrycan - Blue | J40: =PROPER(TRIM(I40)) -> 20L Jerrycan - Blue | K40: 4 | L40: =IF(K40="",0,K40) -> 4 | M40: 600 | N40: =IF(M40="",0,M40) -> 600 | O40: =IF(L40<0,"NEGATIVE QUANTITY","") | P40: =ABS(L40) -> 4 | Q40: =VLOOKUP(H40,'Product Cost Lookup'!A:D,4,FALSE) -> 350 | R40: =VLOOKUP(H40,'Product Cost Lookup'!A:D,3,FALSE) -> Household | S40: =P40*N40 -> 2400 | T40: =P40*Q40 -> 1400 | U40: =S40-T40 -> 1000 | V40: =IF(S40=0,0,U40/S40) -> 0.41666667 | W40: =TEXT(C40,"mmm") -> Jan
A41: 10311 | B41: 45332 | C41: 45332 | D41: Thika | E41: =IF(TRIM(D41)="","Unknown",PROPER(TRIM(D41))) -> Thika | F41: Samuel Kiptoo | G41: =PROPER(TRIM(F41)) -> Samuel Kiptoo | H41: P012 | I41: Garden Hose 20m | J41: =PROPER(TRIM(I41)) -> Garden Hose 20M | K41: 5 | L41: =IF(K41="",0,K41) -> 5 | M41: 1800 | N41: =IF(M41="",0,M41) -> 1800 | O41: =IF(L41<0,"NEGATIVE QUANTITY","") | P41: =ABS(L41) -> 5 | Q41: =VLOOKUP(H41,'Product Cost Lookup'!A:D,4,FALSE) -> 1100 | R41: =VLOOKUP(H41,'Product Cost Lookup'!A:D,3,FALSE) -> Hardware | S41: =P41*N41 -> 9000 | T41: =P41*Q41 -> 5500 | U41: =S41-T41 -> 3500 | V41: =IF(S41=0,0,U41/S41) -> 0.38888889 | W41: =TEXT(C41,"mmm") -> Feb
A42: 10170 | B42: 45336 | C42: 45336 | D42: Nairobi | E42: =IF(TRIM(D42)="","Unknown",PROPER(TRIM(D42))) -> Nairobi | F42: AISHA HASSAN | G42: =PROPER(TRIM(F42)) -> Aisha Hassan | H42: P002 | I42: solar lantern sl-200 | J42: =PROPER(TRIM(I42)) -> Solar Lantern Sl-200 | K42: 5 | L42: =IF(K42="",0,K42) -> 5 | M42: 1500 | N42: =IF(M42="",0,M42) -> 1500 | O42: =IF(L42<0,"NEGATIVE QUANTITY","") | P42: =ABS(L42) -> 5 | Q42: =VLOOKUP(H42,'Product Cost Lookup'!A:D,4,FALSE) -> 900 | R42: =VLOOKUP(H42,'Product Cost Lookup'!A:D,3,FALSE) -> Electronics | S42: =P42*N42 -> 7500 | T42: =P42*Q42 -> 4500 | U42: =S42-T42 -> 3000 | V42: =IF(S42=0,0,U42/S42) -> 0.4 | W42: =TEXT(C42,"mmm") -> Feb
... A46: 10284 | B46: 45358 | C46: 45358 | D46: Thika | E46: =IF(TRIM(D46)="","Unknown",PROPER(TRIM(D46))) -> Thika | F46: samuel kiptoo | G46: =PROPER(TRIM(F46)) -> Samuel Kiptoo | H46: P014 | I46: LED Bulb 9W (Pack of 4) | J46: =PROPER(TRIM(I46)) -> Led Bulb 9W (Pack Of 4) | K46: 5 | L46: =IF(K46="",0,K46) -> 5 | M46: 880 | N46: =IF(M46="",0,M46) -> 880 | O46: =IF(L46<0,"NEGATIVE QUANTITY","") | P46: =ABS(L46) -> 5 | Q46: =VLOOKUP(H46,'Product Cost Lookup'!A:D,4,FALSE) -> 480 | R46: =VLOOKUP(H46,'Product Cost Lookup'!A:D,3,FALSE) -> Electronics | S46: =P46*N46 -> 4400 | T46: =P46*Q46 -> 2400 | U46: =S46-T46 -> 2000 | V46: =IF(S46=0,0,U46/S46) -> 0.45454545 | W46: =TEXT(C46,"mmm") -> Mar
A47: 10125 | B47: 18/01/2024 | C47: 45309 | D47: Thika | E47: =IF(TRIM(D47)="","Unknown",PROPER(TRIM(D47))) -> Thika | F47: Mercy Njeri | G47: =PROPER(TRIM(F47)) -> Mercy Njeri | H47: P013 | I47: Kitchen Knife Set | J47: =PROPER(TRIM(I47)) -> Kitchen Knife Set | K47: 10 | L47: =IF(K47="",0,K47) -> 10 | M47: 1400 | N47: =IF(M47="",0,M47) -> 1400 | O47: =IF(L47<0,"NEGATIVE QUANTITY","") | P47: =ABS(L47) -> 10 | Q47: =VLOOKUP(H47,'Product Cost Lookup'!A:D,4,FALSE) -> 800 | R47: =VLOOKUP(H47,'Product Cost Lookup'!A:D,3,FALSE) -> Kitchenware | S47: =P47*N47 -> 14000 | T47: =P47*Q47 -> 8000 | U47: =S47-T47 -> 6000 | V47: =IF(S47=0,0,U47/S47) -> 0.42857143 | W47: =TEXT(C47,"mmm") -> Jan
A48: 10173 | B48: 45367 | C48: 45367 | D48: Nakuru | E48: =IF(TRIM(D48)="","Unknown",PROPER(TRIM(D48))) -> Nakuru | F48: Brian Mutua | G48: =PROPER(TRIM(F48)) -> Brian Mutua | H48: P001 | I48: 20L Jerrycan - Blue | J48: =PROPER(TRIM(I48)) -> 20L Jerrycan - Blue | K48: 4 | L48: =IF(K48="",0,K48) -> 4 | M48: 550 | N48: =IF(M48="",0,M48) -> 550 | O48: =IF(L48<0,"NEGATIVE QUANTITY","") | P48: =ABS(L48) -> 4 | Q48: =VLOOKUP(H48,'Product Cost Lookup'!A:D,4,FALSE) -> 350 | R48: =VLOOKUP(H48,'Product Cost Lookup'!A:D,3,FALSE) -> Household | S48: =P48*N48 -> 2200 | T48: =P48*Q48 -> 1400 | U48: =S48-T48 -> 800 | V48: =IF(S48=0,0,U48/S48) -> 0.36363636 | W48: =TEXT(C48,"mmm") -> Mar
A49: 10312 | B49: 45294 | C49: 45294 | D49: Mombasa | E49: =IF(TRIM(D49)="","Unknown",PROPER(TRIM(D49))) -> Mombasa | F49: Faith Wanjiru | G49: =PROPER(TRIM(F49)) -> Faith Wanjiru | H49: P011 | I49: Padlock Set (3pc) | J49: =PROPER(TRIM(I49)) -> Padlock Set (3Pc) | K49: 5 | L49: =IF(K49="",0,K49) -> 5 | M49: 650 | N49: =IF(M49="",0,M49) -> 650 | O49: =IF(L49<0,"NEGATIVE QUANTITY","") | P49: =ABS(L49) -> 5 | Q49: =VLOOKUP(H49,'Product Cost Lookup'!A:D,4,FALSE) -> 450 | R49: =VLOOKUP(H49,'Product Cost Lookup'!A:D,3,FALSE) -> Hardware | S49: =P49*N49 -> 3250 | T49: =P49*Q49 -> 2250 | U49: =S49-T49 -> 1000 | V49: =IF(S49=0,0,U49/S49) -> 0.30769231 | W49: =TEXT(C49,"mmm") -> Jan
...

Sheet Product Cost Lookup
A1: Product ID | B1: Product Name | C1: Category | D1: Unit Cost (KES)
A2: P001 | B2: 20L Jerrycan - Blue | C2: Household | D2: 350
A3: P002 | B3: Solar Lantern SL-200 | C3: Electronics | D3: 900
A4: P003 | B4: Rechargeable Torch RT-10 | C4: Electronics | D4: 600
A5: P004 | B5: Cooking Gas Burner CB-2 | C5: Kitchenware | D5: 1200
A6: P005 | B6: Non-Stick Frying Pan 28cm | C6: Kitchenware | D6: 700
A7: P006 | B7: Plastic Storage Basket L | C7: Household | D7: 250
A8: P007 | B8: Mosquito Net - Family Size | C8: Household | D8: 400
A9: P008 | B9: USB Wall Charger UC-5 | C9: Electronics | D9: 300
A10: P009 | B10: Thermos Flask 1L | C10: Kitchenware | D10: 550
A11: P010 | B11: Wheelbarrow - Heavy Duty | C11: Hardware | D11: 3500
A12: P011 | B12: Padlock Set (3pc) | C12: Hardware | D12: 450
A13: P012 | B13: Garden Hose 20m | C13: Hardware | D13: 1100
... A16: P015 | B16: Water Dispenser Stand | C16: Household | D16: 1500

Sheet PIVOT - REGION
A2: Cleaned Region | B2: Sum of Revenue | C2: Sum of Profit
A3: Eldoret | B3: 580680 | C3: 198620
A4: Kisumu | B4: 619050 | C4: 212600
A5: Mombasa | B5: 636960 | C5: 240700
A6: Nairobi | B6: 710700 | C6: 240850
A7: Nakuru | B7: 425560 | C7: 155820
A8: Thika | B8: 517900 | C8: 184380
A9: Unknown | B9: 80600 | C9: 31050
A10: Grand Total | B10: 3571450 | C10: 1264020
H20: =GETPIVOTDATA("Sum of Profit",'PIVOT - REGION'!$A$3) -> 1264020

Sheet PIVOT - SALES REP
A2: Cleaned Sales Rep | B2: Sum of Revenue | C2: Sum of Profit
A3: Aisha Hassan | B3: 300540 | C3: 90840
A4: Brian Mutua | B4: 445850 | C4: 159380
A5: Faith Wanjiru | B5: 412200 | C5: 149800
A6: Grace Achieng | B6: 474600 | C6: 172100
A7: John Mwangi | B7: 388840 | C7: 139190
A8: Mercy Njeri | B8: 485380 | C8: 169260
A9: Peter Otieno | B9: 503840 | C9: 182400
A10: Samuel Kiptoo | B10: 560200 | C10: 201050
A11: Grand Total | B11: 3571450 | C11: 1264020

Sheet PIVOT - CATEGORY
A2: Category | B2: Sum of Revenue | C2: Sum of Profit
A3: Electronics | B3: 618380 | C3: 230300
A4: Hardware | B4: 1359600 | C4: 454150
A5: Household | B5: 779020 | C5: 281020
A6: Kitchenware | B6: 814450 | C6: 298550
A7: Grand Total | B7: 3571450 | C7: 1264020

Sheet PIVOT - TOP 5 PRODUCTS
A2: Cleaned Product Name | B2: Sum of Revenue
A3: Cooking Gas Burner Cb-2 | B3: 306500
A4: Garden Hose 20M | B4: 540250
A5: Kitchen Knife Set | B5: 290150
A6: Water Dispenser Stand | B6: 456600
A7: Wheelbarrow - Heavy Duty | B7: 459650
A8: Grand Total | B8: 2053150

Sheet PIVOT - MONTH
H7: Month | I7: Sum of Revenue | J7: Sum of Profit
H8: Jan | I8: 982630 | J8: 357600
H9: Feb | I9: 857320 | J9: 319560
H10: Mar | I10: 1288420 | J10: 441280
H11: Apr | I11: 16300 | J11: 6400
H12: May | I12: 54650 | J12: 20150
H13: Jun | I13: 159600 | J13: 41100
H14: Jul | I14: 7650 | J14: 3200
H15: Aug | I15: 77480 | J15: 26180
H16: Sep | I16: 10400 | J16: 3400
H17: Oct | I17: 37900 | J17: 13350
H18: Nov | I18: 28100 | J18: 11300
H19: Dec | I19: 51000 | J19: 20500
H20: Grand Total | I20: 3571450 | J20: 1264020

Sheet Dashboard
J2: Highland Distributors Sales Dashboard
H6: Total Revenue | L6: Total Profit
H7: =GETPIVOTDATA("Sum of Revenue",'PIVOT - REGION'!$A$3) -> 3571450 | L7: =GETPIVOTDATA("Sum of Profit",'PIVOT - REGION'!$A$3) -> 1264020
H10: Avg Margin % | L10: Total Orders
H11: =L7/H7 -> 0.35392348 | L11: =COUNTA('Cleaned Sales Data'!A:A)-1 -> 340
J19: Monthly Revenue Chart
J38: Revenue by Region
J58: Top 5 Products by Revenue
J60: Cleaned Product Name | K60: Sum of Revenue
J61: Cooking Gas Burner Cb-2 | K61: 306500
J62: Garden Hose 20M | K62: 540250
J63: Kitchen Knife Set | K63: 290150
J64: Water Dispenser Stand | K64: 456600
J65: Wheelbarrow - Heavy Duty | K65: 459650
J66: Grand Total | K66: 2053150
J73: Slicers

Sheet Data Cleaning notes
J1: Data Cleaning Notes
H6: Issue | J6: Resolution
H7: Mixed Dates | J7: All dates converted to real excel dates
H8: Missing Regions | J8: Set to "Unkown" and used TRIM
H9: Missing Quantities | J9: Set to 0 and flagged for review
H10: Missing Unit Price | J10: Set to 0 and flagged for review
H11: Negative Quantity | J11: Converted using ABS() and flagged for review
H12: Duplicate Rows | J12: Removed 18 duplicates
H13: Sales Rep Formatting | J13: Standardized using PROPER and TRIM
H14: Region Formatting | J14: Standardized using PROPER and TRIM
H15: Product names | J15: Standardized using TRIM
H16: Unit Cost & Category | J16: Added using VLOOKUP from Product Cost Lookup

Sheet Cleaned_Sales Table
A1: Order ID | B1: Order Date | C1: Cleaned Order Date | D1: Region | E1: Cleaned Region | F1: Sales Rep | G1: Cleaned Sales Rep | H1: Product ID | I1: Product Name | J1: Cleaned Product Name | K1: Quantity | L1: New Quantity | M1: Unit Price (KES) | N1: Cleaned Unit Price (KES) | O1: Flags | P1: Cleaned Quantity | Q1: Unit Cost | R1: Category | S1: Revenue | T1: Cost | U1: Profit | V1: Margin % | W1: Month
A2: 10008 | B2: 45306 | C2: 45306 | D2: mombasa | E2: Mombasa | F2: Peter Otieno | G2: Peter Otieno | H2: P013 | I2: Kitchen Knife Set | J2: Kitchen Knife Set | K2: 20 | L2: 20 | M2: 1350 | N2: 1350 | P2: 20 | Q2: 800 | R2: Kitchenware | S2: 27000 | T2: 16000 | U2: 11000 | V2: 0.40740741 | W2: Jan
A3: 10300 | B3: 45364 | C3: 45364 | D3: nakuru | E3: Nakuru | F3: Faith Wanjiru | G3: Faith Wanjiru | H3: P013 | I3: Kitchen Knife Set | J3: Kitchen Knife Set | K3: 6 | L3: 6 | M3: 1350 | N3: 1350 | P3: 6 | Q3: 800 | R3: Kitchenware | S3: 8100 | T3: 4800 | U3: 3300 | V3: 0.40740741 | W3: Mar
A4: 10328 | B4: 45338 | C4: 45338 | D4: Mombasa | E4: Mombasa | F4: Grace Achieng | G4: Grace Achieng | H4: P001 | I4: 20L Jerrycan - Blue | J4: 20L Jerrycan - Blue | K4: 4 | L4: 4 | M4: 600 | N4: 600 | P4: 4 | Q4: 350 | R4: Household | S4: 2400 | T4: 1400 | U4: 1000 | V4: 0.41666667 | W4: Feb
A5: 10216 | B5: 45373 | C5: 45373 | D5: Eldoret | E5: Eldoret | F5: grace achieng | G5: Grace Achieng | H5: P015 | I5: Water Dispenser Stand | J5: Water Dispenser Stand | K5: 10 | L5: 10 | M5: 2300 | N5: 2300 | P5: 10 | Q5: 1500 | R5: Household | S5: 23000 | T5: 15000 | U5: 8000 | V5: 0.34782609 | W5: Mar
A6: 10065 | B6: 45505 | C6: 45505 | D6: KISUMU | E6: Kisumu | F6: Mercy Njeri | G6: Mercy Njeri | H6: P006 | I6: Plastic Storage Basket L | J6: Plastic Storage Basket L | K6: 8 | L6: 8 | M6: 420 | N6: 420 | P6: 8 | Q6: 250 | R6: Household | S6: 3360 | T6: 2000 | U6: 1360 | V6: 0.4047619 | W6: Aug
A7: 10222 | B7: 45339 | C7: 45339 | D7: Mombasa | E7: Mombasa | F7: aisha hassan | G7: Aisha Hassan | H7: P001 | I7: 20L Jerrycan - Blue | J7: 20L Jerrycan - Blue | K7: 5 | L7: 5 | M7: 600 | N7: 600 | P7: 5 | Q7: 350 | R7: Household | S7: 3000 | T7: 1750 | U7: 1250 | V7: 0.41666667 | W7: Feb
A8: 10140 | B8: 45306 | C8: 45306 | D8: Thika | E8: Thika | F8: Faith Wanjiru | G8: Faith Wanjiru | H8: P012 | I8: Garden Hose 20m | J8: Garden Hose 20M | K8: 15 | L8: 15 | M8: 1750 | N8: 1750 | P8: 15 | Q8: 1100 | R8: Hardware | S8: 26250 | T8: 16500 | U8: 9750 | V8: 0.37142857 | W8: Jan
A9: 10268 | B9: 45336 | C9: 45336 | D9: Mombasa | E9: Mombasa | F9: Faith Wanjiru | G9: Faith Wanjiru | H9: P011 | I9: PADLOCK SET (3PC) | J9: Padlock Set (3Pc) | K9: 6 | L9: 6 | M9: 700 | N9: 700 | P9: 6 | Q9: 450 | R9: Hardware | S9: 4200 | T9: 2700 | U9: 1500 | V9: 0.35714286 | W9: Feb
A10: 10025 | B10: 45323 | C10: 45323 | D10: Kisumu | E10: Kisumu | F10: PETER OTIENO | G10: Peter Otieno | H10: P013 | I10: Kitchen Knife Set | J10: Kitchen Knife Set | K10: 2 | L10: 2 | M10: 1350 | N10: 1350 | P10: 2 | Q10: 800 | R10: Kitchenware | S10: 2700 | T10: 1600 | U10: 1100 | V10: 0.40740741 | W10: Feb
A11: 10205 | B11: 45599 | C11: 45599 | D11: MOMBASA | E11: Mombasa | F11: Grace Achieng | G11: Grace Achieng | H11: P008 | I11: USB Wall Charger UC-5 | J11: Usb Wall Charger Uc-5 | K11: 2 | L11: 2 | M11: 500 | N11: 500 | P11: 2 | Q11: 300 | R11: Electronics | S11: 1000 | T11: 600 | U11: 400 | V11: 0.4 | W11: Nov
A12: 10188 | B12: 45370 | C12: 45370 | D12: Thika | E12: Thika | F12: Peter Otieno | G12: Peter Otieno | H12: P008 | I12: USB Wall Charger UC-5 | J12: Usb Wall Charger Uc-5 | K12: 6 | L12: 6 | M12: 500 | N12: 500 | P12: 6 | Q12: 300 | R12: Electronics | S12: 3000 | T12: 1800 | U12: 1200 | V12: 0.4 | W12: Mar
A13: 10152 | B13: 45321 | C13: 45321 | D13: Nakuru | E13: Nakuru | F13: faith wanjiru | G13: Faith Wanjiru | H13: P008 | I13: USB Wall Charger UC-5 | J13: Usb Wall Charger Uc-5 | K13: 12 | L13: 12 | M13: 500 | N13: 500 | P13: 12 | Q13: 300 | R13: Electronics | S13: 6000 | T13: 3600 | U13: 2400 | V13: 0.4 | W13: Jan
A14: 10137 | B14: 45325 | C14: 45325 | D14: Nakuru | E14: Nakuru | F14: Faith Wanjiru | G14: Faith Wanjiru | H14: P008 | I14: USB Wall Charger UC-5 | J14: Usb Wall Charger Uc-5 | K14: -5 | L14: -5 | M14: 500 | N14: 500 | O14: NEGATIVE QUANTITY | P14: 5 | Q14: 300 | R14: Electronics | S14: 2500 | T14: 1500 | U14: 1000 | V14: 0.4 | W14: Feb
A15: 10107 | B15: 45296 | C15: 45296 | D15: Kisumu | E15: Kisumu | F15: FAITH WANJIRU | G15: Faith Wanjiru | H15: P001 | I15: 20L Jerrycan - Blue | J15: 20L Jerrycan - Blue | K15: 4 | L15: 4 | M15: 500 | N15: 500 | P15: 4 | Q15: 350 | R15: Household | S15: 2000 | T15: 1400 | U15: 600 | V15: 0.3 | W15: Jan
A16: 10067 | B16: 45346 | C16: 45346 | D16: thika | E16: Thika | F16: Samuel Kiptoo | G16: Samuel Kiptoo | H16: P008 | I16: USB Wall Charger UC-5 | J16: Usb Wall Charger Uc-5 | K16: 5 | L16: 5 | M16: 500 | N16: 500 | P16: 5 | Q16: 300 | R16: Electronics | S16: 2500 | T16: 1500 | U16: 1000 | V16: 0.4 | W16: Feb
A17: 10030 | B17: 45445 | C17: 45445 | D17: Mombasa | E17: Mombasa | F17: Brian Mutua | G17: Brian Mutua | H17: P013 | I17: Kitchen Knife Set | J17: Kitchen Knife Set | K17: 15 | L17: 15 | M17: 1400 | N17: 1400 | P17: 15 | Q17: 800 | R17: Kitchenware | S17: 21000 | T17: 12000 | U17: 9000 | V17: 0.42857143 | W17: Jun
A18: 10109 | B18: 45597 | C18: 45597 | D18: thika | E18: Thika | F18: Brian Mutua | G18: Brian Mutua | H18: P002 | I18: Solar Lantern SL200 | J18: Solar Lantern Sl200 | K18: 8 | L18: 8 | M18: 1550 | N18: 1550 | P18: 8 | Q18: 900 | R18: Electronics | S18: 12400 | T18: 7200 | U18: 5200 | V18: 0.41935484 | W18: Nov
A19: 10218 | B19: 45365 | C19: 45365 | D19: Thika | E19: Thika | F19: Faith Wanjiru | G19: Faith Wanjiru | H19: P003 | I19: RECHARGEABLE TORCH RT-10 | J19: Rechargeable Torch Rt-10 | K19: 10 | L19: 10 | M19: 900 | N19: 900 | P19: 10 | Q19: 600 | R19: Electronics | S19: 9000 | T19: 6000 | U19: 3000 | V19: 0.33333333 | W19: Mar
A20: 10228 | B20: 45381 | C20: 45381 | D20: Thika | E20: Thika | F20: Grace Achieng | G20: Grace Achieng | H20: P014 | I20: LED Bulb 9W (Pack of 4) | J20: Led Bulb 9W (Pack Of 4) | K20: 4 | L20: 4 | M20: 780 | N20: 780 | P20: 4 | Q20: 480 | R20: Electronics | S20: 3120 | T20: 1920 | U20: 1200 | V20: 0.38461538 | W20: Mar
A21: 10111 | B21: 21/01/2024 | C21: 45312 | D21: Nairobi | E21: Nairobi | F21: PETER OTIENO | G21: Peter Otieno | H21: P014 | I21: LED Bulb 9W (Pack of 4) | J21: Led Bulb 9W (Pack Of 4) | K21: 15 | L21: 15 | M21: 830 | N21: 830 | P21: 15 | Q21: 480 | R21: Electronics | S21: 12450 | T21: 7200 | U21: 5250 | V21: 0.42168675 | W21: Jan
A22: 10255 | B22: 45446 | C22: 45446 | D22: Eldoret | E22: Eldoret | F22: Faith Wanjiru | G22: Faith Wanjiru | H22: P011 | I22: Padlock Set (3pc) | J22: Padlock Set (3Pc) | K22: 20 | L22: 20 | M22: 750 | N22: 750 | P22: 20 | Q22: 450 | R22: Hardware | S22: 15000 | T22: 9000 | U22: 6000 | V22: 0.4 | W22: Jun
A23: 10236 | B23: 45335 | C23: 45335 | D23: Thika | E23: Thika | F23: Faith Wanjiru | G23: Faith Wanjiru | H23: P011 | I23: PADLOCK SET (3PC) | J23: Padlock Set (3Pc) | K23: 12 | L23: 12 | M23: 750 | N23: 750 | P23: 12 | Q23: 450 | R23: Hardware | S23: 9000 | T23: 5400 | U23: 3600 | V23: 0.4 | W23: Feb
A24: 10055 | B24: 45378 | C24: 45378 | D24: Kisumu | E24: Kisumu | F24: John Mwangi | G24: John Mwangi | H24: P013 | I24: Kitchen Knife Set | J24: Kitchen Knife Set | K24: 3 | L24: 3 | M24: 1350 | N24: 1350 | P24: 3 | Q24: 800 | R24: Kitchenware | S24: 4050 | T24: 2400 | U24: 1650 | V24: 0.40740741 | W24: Mar
A25: 10090 | B25: 45335 | C25: 45335 | D25: Mombasa | E25: Mombasa | F25: Mercy Njeri | G25: Mercy Njeri | H25: P013 | I25: Kitchen Knife Set | J25: Kitchen Knife Set | K25: 3 | L25: 3 | M25: 1250 | N25: 1250 | P25: 3 | Q25: 800 | R25: Kitchenware | S25: 3750 | T25: 2400 | U25: 1350 | V25: 0.36 | W25: Feb
A26: 10197 | B26: 45338 | C26: 45338 | D26: NAKURU | E26: Nakuru | F26: Peter Otieno | G26: Peter Otieno | H26: P003 | I26: RECHARGEABLE TORCH RT-10 | J26: Rechargeable Torch Rt-10 | K26: 1 | L26: 1 | M26: 1050 | N26: 1050 | P26: 1 | Q26: 600 | R26: Electronics | S26: 1050 | T26: 600 | U26: 450 | V26: 0.42857143 | W26: Feb
A27: 10242 | B27: 45368 | C27: 45368 | E27: Unknown | F27: MERCY NJERI | G27: Mercy Njeri | H27: P007 | I27: MOSQUITO NET - FAMILY SIZE | J27: Mosquito Net - Family Size | K27: 20 | L27: 20 | M27: 650 | N27: 650 | P27: 20 | Q27: 400 | R27: Household | S27: 13000 | T27: 8000 | U27: 5000 | V27: 0.38461538 | W27: Mar
A28: 10289 | B28: 18/02/2024 | C28: 45340 | D28: Nakuru | E28: Nakuru | F28: Peter Otieno | G28: Peter Otieno | H28: P002 | I28: Solar Lantern SL-200 | J28: Solar Lantern Sl-200 | K28: 1 | L28: 1 | M28: 1450 | N28: 1450 | P28: 1 | Q28: 900 | R28: Electronics | S28: 1450 | T28: 900 | U28: 550 | V28: 0.37931034 | W28: Feb
A29: 10108 | B29: 45375 | C29: 45375 | D29: KISUMU | E29: Kisumu | F29: Samuel Kiptoo | G29: Samuel Kiptoo | H29: P002 | I29: solar lantern sl-200 | J29: Solar Lantern Sl-200 | K29: 6 | L29: 6 | M29: 1500 | N29: 1500 | P29: 6 | Q29: 900 | R29: Electronics | S29: 9000 | T29: 5400 | U29: 3600 | V29: 0.4 | W29: Mar
A30: 10087 | B30: 45342 | C30: 45342 | E30: Unknown | F30: John Mwangi | G30: John Mwangi | H30: P001 | I30: 20L Jerrycan - Blue | J30: 20L Jerrycan - Blue | K30: 4 | L30: 4 | M30: 550 | N30: 550 | P30: 4 | Q30: 350 | R30: Household | S30: 2200 | T30: 1400 | U30: 800 | V30: 0.36363636 | W30: Feb
A31: 10263 | B31: 45328 | C31: 45328 | D31: Thika | E31: Thika | F31: Samuel Kiptoo | G31: Samuel Kiptoo | H31: P003 | I31: Rechargeable Torch RT-10 | J31: Rechargeable Torch Rt-10 | K31: 1 | L31: 1 | M31: 950 | N31: 950 | P31: 1 | Q31: 600 | R31: Electronics | S31: 950 | T31: 600 | U31: 350 | V31: 0.36842105 | W31: Feb
A32: 10038 | B32: 45376 | C32: 45376 | D32: Nairobi | E32: Nairobi | F32: Grace Achieng | G32: Grace Achieng | H32: P011 | I32: Padlock Set (3pc) | J32: Padlock Set (3Pc) | K32: 8 | L32: 8 | M32: 700 | N32: 700 | P32: 8 | Q32: 450 | R32: Hardware | S32: 5600 | T32: 3600 | U32: 2000 | V32: 0.35714286 | W32: Mar
A33: 10148 | B33: 45299 | C33: 45299 | D33: Eldoret | E33: Eldoret | F33: Brian Mutua | G33: Brian Mutua | H33: P007 | I33: Mosquito Net - Family Size | J33: Mosquito Net - Family Size | K33: 12 | L33: 12 | M33: 750 | N33: 750 | P33: 12 | Q33: 400 | R33: Household | S33: 9000 | T33: 4800 | U33: 4200 | V33: 0.46666667 | W33: Jan
A34: 10180 | B34: 45382 | C34: 45382 | D34: Eldoret | E34: Eldoret | F34: Brian Mutua | G34: Brian Mutua | H34: P003 | I34: Rechargeable Torch RT-10 | J34: Rechargeable Torch Rt-10 | K34: 15 | L34: 15 | M34: 950 | N34: 950 | P34: 15 | Q34: 600 | R34: Electronics | S34: 14250 | T34: 9000 | U34: 5250 | V34: 0.36842105 | W34: Mar
A35: 10027 | B35: 45296 | C35: 45296 | D35: Nairobi | E35: Nairobi | F35: Brian Mutua | G35: Brian Mutua | H35: P006 | I35: plastic storage basket l | J35: Plastic Storage Basket L | K35: 6 | L35: 6 | M35: 470 | N35: 470 | P35: 6 | Q35: 250 | R35: Household | S35: 2820 | T35: 1500 | U35: 1320 | V35: 0.46808511 | W35: Jan
A36: 10276 | B36: 45310 | C36: 45310 | D36: Mombasa | E36: Mombasa | F36: Peter Otieno | G36: Peter Otieno | H36: P004 | I36: Cooking Gas Burner CB-2 | J36: Cooking Gas Burner Cb-2 | K36: 15 | L36: 15 | M36: 1850 | N36: 1850 | P36: 15 | Q36: 1200 | R36: Kitchenware | S36: 27750 | T36: 18000 | U36: 9750 | V36: 0.35135135 | W36: Jan
A37: 10184 | B37: 45308 | C37: 45308 | D37: ELDORET | E37: Eldoret | F37: Aisha Hassan | G37: Aisha Hassan | H37: P013 | I37: Kitchen Knife Set | J37: Kitchen Knife Set | K37: 6 | L37: 6 | M37: 1250 | N37: 1250 | P37: 6 | Q37: 800 | R37: Kitchenware | S37: 7500 | T37: 4800 | U37: 2700 | V37: 0.36 | W37: Jan
A38: 10062 | B38: 45375 | C38: 45375 | D38: Mombasa | E38: Mombasa | F38: Aisha Hassan | G38: Aisha Hassan | H38: P001 | I38: 20L Jerrycan - Blue | J38: 20L Jerrycan - Blue | K38: 3 | L38: 3 | M38: 650 | N38: 650 | P38: 3 | Q38: 350 | R38: Household | S38: 1950 | T38: 1050 | U38: 900 | V38: 0.46153846 | W38: Mar
A39: 10296 | B39: 45375 | C39: 45375 | D39: ELDORET | E39: Eldoret | F39: Samuel Kiptoo | G39: Samuel Kiptoo | H39: P012 | I39: Garden Hose 20m | J39: Garden Hose 20M | K39: 15 | L39: 15 | M39: 1650 | N39: 1650 | P39: 15 | Q39: 1100 | R39: Hardware | S39: 24750 | T39: 16500 | U39: 8250 | V39: 0.33333333 | W39: Mar
A40: 10186 | B40: 45303 | C40: 45303 | D40: Thika | E40: Thika | F40: Grace Achieng | G40: Grace Achieng | H40: P001 | I40: 20L Jerrycan - Blue | J40: 20L Jerrycan - Blue | K40: 4 | L40: 4 | M40: 600 | N40: 600 | P40: 4 | Q40: 350 | R40: Household | S40: 2400 | T40: 1400 | U40: 1000 | V40: 0.41666667 | W40: Jan
...
